Workbook

Sheet Assumptions
A1: Cheerio AI — Customer Support Assistant Financial, Cost & Billing Model
A2: Live financial engineering model for AI-driven WhatsApp support automation • All baseline inputs and operational parameters
A4: Ref # | B4: Parameter / Assumption Name | C4: Value | D4: Unit | E4: Type / Source | F4: Notes & Operational Rationale
A5: 1. CUSTOMER BASE & QUERY VOLUME ASSUMPTIONS
A6: A_BUS_ACT | B6: Active businesses | C6: 5000 | D6: Businesses | E6: Platform Input | F6: Total active/paying SMB customer accounts on Cheerio WhatsApp platform
A7: A_BUS_SETUP | B7: Share of businesses in setup phase | C7: 0.15 | D7: % | E7: Platform Input | F7: Proportion of businesses actively onboarding, configuring WABA & templates
A8: A_QRY_SETUP | B8: Queries per month, setup-phase business | C8: 3 | D8: Queries / biz / mo | E8: Empirical Input | F8: High inquiry frequency during initial WABA setup, verification & catalog sync
A9: A_QRY_EST | B9: Queries per month, established business | C9: 0.4 | D9: Queries / biz / mo | E9: Empirical Input | F9: Steady-state support volume for live operational campaigns and broadcast flows
A10: 2. AI RESOLUTION TARGETS & ISSUE MIX (STEADY STATE)
A11: A_RES_M3 | B11: AI resolution rate (Month-3 target) | C11: 0.4 | D11: % | E11: Target Input | F11: Conservative milestone target for early deployment across core intents
A12: A_RES_SS | B12: AI resolution rate (Steady state) | C12: =E20 | D12: % | E12: Model Formula | F12: Weighted average resolution rate calculated from category breakdown below (=47.75%)
A13: Cat ID | B13: Support Issue Category | C13: Mix % | D13: AI Resolution % | E13: Weighted Contribution | F13: Scope & Complexity Description
A14: CAT_1 | B14: Setup & Business Verification | C14: 0.25 | D14: 0.5 | E14: =C14*D14 | F14: Meta WABA phone registration, green tick, display name, ID verification
A15: CAT_2 | B15: Message Templates | C15: 0.2 | D15: 0.65 | E15: =C15*D15 | F15: Category rejections (Utility vs Marketing), variable formatting, buttons
A16: CAT_3 | B16: Delivery Failures & Errors | C16: 0.15 | D16: 0.6 | E16: =C16*D16 | F16: Meta error codes 131026, 131047, recipient opt-in, spam block diagnostic
A17: CAT_4 | B17: Chatbot Automation & Flows | C17: 0.15 | D17: 0.45 | E17: =C17*D17 | F17: Flow builder branching, keyword triggers, webhook handoff rules
A18: CAT_5 | B18: E-commerce & CRM Integrations | C18: 0.1 | D18: 0.35 | E18: =C18*D18 | F18: Shopify order sync, WooCommerce webhooks, Zapier connection errors
A19: CAT_6 | B19: Other / Billing / Account Inquiries | C19: 0.15 | D19: 0.2 | E19: =C19*D19 | F19: Out-of-scope queries (pricing, refunds, edge cases); routed to ticket
A20: CAT_TOT | B20: Total Mix & Steady-State Resolution | C20: =SUM(C14:C19) | D20: - | E20: =SUM(E14:E19) | F20: 100.0% mix yields 47.75% steady-state blended AI resolution rate
A21: 3. CONVERSATION TOKEN & LLM COST ASSUMPTIONS
A22: A_MDL_SEL | B22: Selected AI Model | C22: Haiku 4.5 | D22: Model Selector | E22: Dropdown / Input | F22: Choose 'Haiku 4.5' (production default) or 'Sonnet 4.6' (deep reasoning)
A23: A_TURNS | B23: Turns per conversation | C23: 5 | D23: Turns / conv | E23: Empirical Input | F23: Average back-and-forth user & assistant exchanges per support thread
A24: A_IN_TOK | B24: Input tokens per turn | C24: 3500 | D24: Tokens / turn | E24: Architecture Input | F24: Includes system instructions, account state (WABA, templates), conversation history
A25: A_OUT_TOK | B25: Output tokens per turn | C25: 250 | D25: Tokens / turn | E25: Architecture Input | F25: Concise, plain-language assistant answer, suggested fix card, and action payload
A26: A_BUF | B26: Buffer for retries & testing | C26: 0.3 | D26: % | E26: Safety Margin | F26: 30% buffer covering internal test suites, tool retries, guardrails & evals
A27: A_FX_RATE | B27: USD to INR exchange rate | C27: 88 | D27: INR / USD | E27: Financial Input | F27: Foreign exchange conversion rate for API compute billing in INR
A28: Model ID | B28: Model Reference | C28: Input Price ($/1M) | D28: Output Price ($/1M) | E28: Blended Base $/Conv | F28: Anthropic API Pricing Tier
A29: MDL_HAIKU | B29: Claude Haiku 4.5 | C29: 1 | D29: 5 | E29: =(C23*C24/1000000)*C29+(C23*C25/1000000)*D29 | F29: Default production model: high speed, ultra-low cost, structured fixes
A30: MDL_SONNET | B30: Claude Sonnet 4.6 | C30: 3 | D30: 15 | E30: =(C23*C24/1000000)*C30+(C23*C25/1000000)*D30 | F30: Alternative model: advanced reasoning for complex multi-turn workflows
A31: MDL_ACTIVE | B31: Active Model API Rate ($/1M) | C31: =IF(C22="Sonnet 4.6",C30,C29) | D31: =IF(C22="Sonnet 4.6",D30,D29) | E31: =IF(C22="Sonnet 4.6",E30,E29) | F31: Live rate dynamically linked to Cell C22 model selector
A32: 4. SUPPORT TEAM LABOR & CAPACITY ECONOMICS
A33: A_AG_SAL | B33: Agent monthly salary | C33: 25000 | D33: INR / month | E33: Labor Input | F33: Base monthly salary for L1 customer support specialist in India (Jaipur/Tier-2)
A34: A_AG_OVH | B34: Agent benefits & overhead load | C34: 0.3 | D34: % | E34: Labor Input | F34: Provident fund (PF), health insurance, workspace, laptop, and Team Lead ratio
A35: A_AG_TOT | B35: Total loaded monthly cost per agent | C35: =C33*(1+C34) | D35: INR / month | E35: Model Formula | F35: Full cost to company (CTC) including 30% operational overhead (=₹32,500)
A36: A_AG_HRS | B36: Working hours per month | C36: 176 | D36: Hours / month | E36: Standard Input | F36: 22 working days per month * 8 scheduled shift hours per day
A37: A_AG_UTL | B37: Agent productive utilisation | C37: 0.7 | D37: % | E37: Ops Input | F37: 70% effective ticket handling; 30% for shift handover, breaks, QA coaching
A38: A_AG_PRD_HRS | B38: Productive hours per agent / month | C38: =C36*C37 | D38: Hours / month | E38: Model Formula | F38: Net effective time dedicated to active customer ticket resolution (=123.2 hrs)
A39: A_AG_HR_CST | B39: Loaded cost per productive hour | C39: =C35/C38 | D39: INR / hour | E39: Model Formula | F39: Fully-loaded operational cost per hour of live human agent handling (=₹263.80)
A40: A_AG_MIN_CST | B40: Loaded cost per productive minute | C40: =C39/60 | D40: INR / minute | E40: Model Formula | F40: Labor cost per ticket minute used for handle time economics (=₹4.40)
A41: 5. HANDLE TIME, PLATFORM FIXED COSTS & BUSINESS RULES
...

Sheet Volume
A1: Cheerio AI — Customer Support Query Volume Modeling
A2: Monthly inbound query generation across setup vs established businesses • AI resolution vs escalation breakdown
A4: 1. BUSINESS SEGMENTATION & INBOUND QUERY GENERATION
A5: Business Segment | B5: Share of Accounts | C5: Active Accounts | D5: Queries / Biz / Mo | E5: Monthly Query Volume | F5: Share of Total Queries
A6: Setup-Phase Businesses | B6: =Assumptions!C7 | C6: =Assumptions!C6*B6 | D6: =Assumptions!C8 | E6: =C6*D6 | F6: =E6/$E$8
A7: Established Businesses | B7: =1-B6 | C7: =Assumptions!C6*B7 | D7: =Assumptions!C9 | E7: =C7*D7 | F7: =E7/$E$8
A8: Total Active Customer Base | B8: =SUM(B6:B7) | C8: =SUM(C6:C7) | D8: =E8/C8 | E8: =SUM(E6:E7) | F8: =SUM(F6:F7)
A10: 2. AI RESOLUTION & HUMAN ESCALATION PROJECTIONS
A11: Performance Metric | B11: Status Quo (No AI) | C11: Month-3 Target (40% Res) | D11: Steady State (47.75% Res) | E11: Variance (Steady vs Target) | F11: Model Formula & Reference
A12: Total Inbound Customer Queries | B12: =E8 | C12: =E8 | D12: =E8 | E12: =D12-C12 | F12: Baseline inbound monthly support inquiry volume
A13: AI Self-Serve Resolution Rate % | B13: 0 | C13: =Assumptions!C11 | D13: =Assumptions!C12 | E13: =D13-C13 | F13: AI resolution capability (40% target vs 47.75% steady state)
A14: Queries Resolved by AI Assistant | B14: 0 | C14: =C12*C13 | D14: =D12*D13 | E14: =D14-C14 | F14: Queries successfully solved without human touch (Target: 1,580 | Steady: 1,886)
A15: Queries Escalated to Human Support | B15: =B12 | C15: =C12*(1-C13) | D15: =D12*(1-D13) | E15: =D15-C15 | F15: Residual inquiries requiring human agent handling (Target: 2,370 | Steady: 2,064)
A16: Human Escalation Rate % | B16: 1 | C16: =C15/C12 | D16: =D15/D12 | E16: =D16-C16 | F16: Share of tickets routed to human queue (Target: 60.0% | Steady: 52.25%)
A17: Net Ticket Deflection Rate % | B17: 0 | C17: =C14/C12 | D17: =D14/D12 | E17: =D17-C17 | F17: Reduction in ticket volume reaching human support queue
A19: 3. STEADY-STATE INBOUND VOLUME BREAKDOWN BY ISSUE CATEGORY
A20: Category ID | B20: Support Category | C20: Mix % | D20: Total Inbound Queries | E20: AI Resolution % | F20: Resolved by AI | G20: Escalated to Human | H20: Escalation Rate %
A21: CAT_1 | B21: Setup & Business Verification | C21: =Assumptions!C14 | D21: =$E$8*C21 | E21: =Assumptions!D14 | F21: =D21*E21 | G21: =D21-F21 | H21: =G21/D21
A22: CAT_2 | B22: Message Templates | C22: =Assumptions!C15 | D22: =$E$8*C22 | E22: =Assumptions!D15 | F22: =D22*E22 | G22: =D22-F22 | H22: =G22/D22
A23: CAT_3 | B23: Delivery Failures & Errors | C23: =Assumptions!C16 | D23: =$E$8*C23 | E23: =Assumptions!D16 | F23: =D23*E23 | G23: =D23-F23 | H23: =G23/D23
A24: CAT_4 | B24: Chatbot Automation & Flows | C24: =Assumptions!C17 | D24: =$E$8*C24 | E24: =Assumptions!D17 | F24: =D24*E24 | G24: =D24-F24 | H24: =G24/D24
A25: CAT_5 | B25: E-commerce & CRM Integrations | C25: =Assumptions!C18 | D25: =$E$8*C25 | E25: =Assumptions!D18 | F25: =D25*E25 | G25: =D25-F25 | H25: =G25/D25
A26: CAT_6 | B26: Other / Billing / Account Inquiries | C26: =Assumptions!C19 | D26: =$E$8*C26 | E26: =Assumptions!D19 | F26: =D26*E26 | G26: =D26-F26 | H26: =G26/D26
A27: TOTAL | B27: Total Steady-State Volume | C27: =SUM(C21:C26) | D27: =SUM(D21:D26) | E27: =F27/D27 | F27: =SUM(F21:F26) | G27: =SUM(G21:G26) | H27: =G27/D27

Sheet Cost
A1: Cheerio AI — Assistant Compute & Infrastructure Cost Architecture
A2: Per-conversation token unit economics • API inference compute costs • Monthly platform hosting & cost to serve
A4: 1. PER-CONVERSATION TOKEN & COMPUTE ARCHITECTURE
A5: Ref # | B5: Token / Cost Parameter | C5: Value | D5: Unit | E5: Calculation Formula | F5: Architectural Driver & Technical Note
A6: C_MDL | B6: Active Foundation Model | C6: =Assumptions!C22 | D6: - | E6: =Assumptions!C22 | F6: Production LLM (Anthropic Claude Haiku 4.5)
A7: C_TRN | B7: Conversation Turns per Session | C7: =Assumptions!C23 | D7: - | E7: =Assumptions!C23 | F7: Average turn depth per support interaction
A8: C_IN_TOK | B8: Input Tokens per Conversation | C8: =C7*Assumptions!C24 | D8: Tokens | E8: =Turns * Input Tokens per Turn | F8: System prompt, account metadata, context injection & chat history (17,500 tok)
A9: C_OUT_TOK | B9: Output Tokens per Conversation | C9: =C7*Assumptions!C25 | D9: Tokens | E9: =Turns * Output Tokens per Turn | F9: Concise 1-step assistant replies and structured fix card payloads (1,250 tok)
A10: C_TOT_TOK | B10: Total Tokens per Conversation | C10: =C8+C9 | D10: Tokens | E10: =Input Tokens + Output Tokens | F10: 18,750 total tokens processed per customer conversation
A11: C_IN_USD | B11: Input Compute Cost (Base) | C11: =(C8/1000000)*Assumptions!C31 | D11: USD / conv | E11: =(Input Tokens / 1M) * Input Rate | F11: $0.017500 base input cost ($1.00 / 1M tokens)
A12: C_OUT_USD | B12: Output Compute Cost (Base) | C12: =(C9/1000000)*Assumptions!D31 | D12: USD / conv | E12: =(Output Tokens / 1M) * Output Rate | F12: $0.006250 base output cost ($5.00 / 1M tokens)
A13: C_BASE_USD | B13: Base API Cost per Conversation | C13: =C11+C12 | D13: USD / conv | E13: =Input Cost + Output Cost | F13: $0.023750 unbuffered base compute per conversation
A14: C_BUF_PCT | B14: Buffer for Retries, Evals & Testing | C14: =Assumptions!C26 | D14: - | E14: =Assumptions!C26 | F14: 30.0% safety margin for retries, tool execution failures & guardrails
A15: C_BUF_USD | B15: Total Buffered Cost per Conversation (USD) | C15: =C13*(1+C14) | D15: USD / conv | E15: =Base Cost * (1 + Buffer %) | F15: $0.030875 fully buffered cost per conversation
A16: C_FX_RATE | B16: USD to INR Exchange Rate | C16: =Assumptions!C27 | D16: - | E16: =Assumptions!C27 | F16: Foreign exchange rate (₹88.00 per USD)
A17: C_INR_CONV | B17: Total AI Cost per Conversation (INR) | C17: =C15*C16 | D17: INR / conv | E17: =Buffered USD * FX Rate | F17: ₹2.72 per customer conversation (Expected: about Rs 2.72)
A19: 2. MONTHLY AI & PLATFORM INFRASTRUCTURE EXPENDITURE
A20: Cost Category | B20: Component Scope Description | C20: Monthly Volume | D20: Unit Cost (INR) | E20: Monthly Cost (INR) | F20: % of Total AI Spend
A21: Variable AI API Compute Cost | B21: Claude Haiku 4.5 LLM inference API calls (incl. 30% retry buffer) | C21: =Volume!E8 | D21: =C17 | E21: =C21*D21 | F21: =E21/$E$23
A22: Fixed Platform Upkeep & Infra | B22: Managed vector database, cloud server, Langfuse logging & 0.25 FTE dev upkeep | C22: 1 | D22: =Assumptions!C44 | E22: =C22*D22 | F22: =E22/$E$23
A23: Total Monthly AI & Platform Cost | B23: Fully-loaded operating cost of Ask Cheerio support system | C23: =C21 | D23: - | E23: =SUM(E21:E22) | F23: =SUM(F21:F22)
A25: 3. COST TO SERVE PER ACTIVE BUSINESS
A26: Cost to Serve Dimension | B26: Monthly Cost (INR) | C26: Active Businesses | D26: Cost / Business / Mo | E26: Annual Cost / Business | F26: Commercial Implication
A27: Variable AI Compute Cost to Serve | B27: =E21 | C27: =Assumptions!C6 | D27: =B27/C27 | E27: =D27*12 | F27: Marginal compute COGS per customer per month (₹2.15/mo)
A28: Fully Loaded Platform Cost to Serve | B28: =E23 | C28: =Assumptions!C6 | D28: =B28/C28 | E28: =D28*12 | F28: Full platform cost including fixed infra upkeep (₹12.15/mo)
A30: 4. MODEL SENSITIVITY: CLAUDE HAIKU 4.5 vs CLAUDE SONNET 4.6
A31: Model Architecture | B31: Input $/1M | C31: Output $/1M | D31: Base USD/Conv | E31: Buffered USD | F31: Cost / Conv (INR) | G31: Monthly AI Cost (3,950 convs) | H31: Cost / Biz / Mo
A32: Claude Haiku 4.5 (Production Default) | B32: =Assumptions!C29 | C32: =Assumptions!D29 | D32: =Assumptions!E29 | E32: =D32*(1+Assumptions!$C$26) | F32: =E32*Assumptions!$C$27 | G32: =Volume!$E$8*F32 | H32: =G32/Assumptions!$C$6
A33: Claude Sonnet 4.6 (Alternative) | B33: =Assumptions!C30 | C33: =Assumptions!D30 | D33: =Assumptions!E30 | E33: =D33*(1+Assumptions!$C$26) | F33: =E33*Assumptions!$C$27 | G33: =Volume!$E$8*F33 | H33: =G33/Assumptions!$C$6
A34: Variance (Sonnet 4.6 vs Haiku 4.5) | B34: =B33-B32 | C34: =C33-C32 | D34: =D33-D32 | E34: =E33-E32 | F34: =F33-F32 | G34: =G33-G32 | H34: =H33-H32

Sheet Savings
A1: Cheerio AI — Support Operations Savings & ROI Model
A2: Comparative labor economics • Unassisted vs AI-assisted ticket handling • Net financial savings & capacity unlocked
A4: 1. HUMAN SUPPORT LABOR UNIT ECONOMICS
A5: Ref # | B5: Labor Economics Parameter | C5: Value | D5: Unit | E5: Calculation Formula | F5: Operational Interpretation
A6: L_SAL | B6: Base Agent Monthly Salary | C6: =Assumptions!C33 | D6: - | E6: =Assumptions!C33 | F6: Base compensation for L1 support specialist in Jaipur / Tier-2 India
A7: L_LOAD | B7: Benefits, Infrastructure & Overhead Load | C7: =Assumptions!C34 | D7: - | E7: =Assumptions!C34 | F7: 30.0% fully loaded employer burden (PF, health, laptop, Team Lead overhead)
A8: L_CTC | B8: Total Loaded Monthly Cost per Agent | C8: =C6*(1+C7) | D8: - | E8: =Base Salary * (1 + Overhead %) | F8: ₹32,500 loaded cost to company per support specialist
A9: L_HRS | B9: Working Hours per Month | C9: =Assumptions!C36 | D9: - | E9: =Assumptions!C36 | F9: 176 hours scheduled (22 working days * 8 hours / shift)
A10: L_UTL | B10: Agent Productive Queue Utilisation | C10: =Assumptions!C37 | D10: - | E10: =Assumptions!C37 | F10: 70.0% productive queue time (remaining 30% for breaks, handovers & QA coaching)
A11: L_PRD_HRS | B11: Productive Handling Hours per Month | C11: =C9*C10 | D11: - | E11: =Working Hours * Utilisation % | F11: 123.2 net effective ticket-handling hours per agent
A12: L_HR_RATE | B12: Loaded Cost per Productive Hour | C12: =C8/C11 | D12: INR / hr | E12: =Loaded Cost / Productive Hours | F12: ₹263.80 fully loaded hourly cost of human support labor
A13: L_MIN_RATE | B13: Loaded Cost per Productive Minute | C13: =C12/60 | D13: INR / min | E13: =Hourly Cost / 60 min | F13: ₹4.40 labor cost per productive ticket handling minute
A14: L_HT_UNAST | B14: Unassisted Ticket Handle Time | C14: =Assumptions!C42 | D14: Minutes | E14: =Assumptions!C42 | F14: 18.0 minutes per unassisted ticket (reading logs, diagnosing, drafting)
A15: L_CST_UNAST | B15: Cost per Human Ticket @ 18 min (Unassisted) | C15: =C13*C14 | D15: INR / ticket | E15: =Minute Rate * 18 min | F15: ₹79.14 cost per unassisted ticket (Status Quo benchmark)
A16: L_HT_ESCAL | B16: Escalated Ticket Handle Time (with AI Summary) | C16: =Assumptions!C43 | D16: Minutes | E16: =Assumptions!C43 | F16: 12.0 minutes per escalated ticket (33.3% faster due to pre-packaged handoff card)
A17: L_CST_ESCAL | B17: Cost per Escalated Ticket @ 12 min (Assisted) | C17: =C13*C16 | D17: INR / ticket | E17: =Minute Rate * 12 min | F17: ₹52.76 cost per escalated ticket with full context
A18: L_SAV_TKT | B18: Labor Saving per Escalated Ticket | C18: =C15-C17 | D18: INR / ticket | E18: =Unassisted Cost - Escalated Cost | F18: ₹26.38 labor saving per ticket handed off to human support
A20: 2. COMPREHENSIVE MONTHLY COMPARISON: HUMAN-ONLY vs WITH-ASSISTANT
A21: Operational & Financial Dimension | B21: Status Quo: Human-Only Support | C21: With Assistant: Month-3 Target (40%) | D21: With Assistant: Steady State (47.75%) | E21: Monthly Variance (Target vs Status Quo) | F21: Calculation Logic & Reference
A22: Total Monthly Inbound Inquiries | B22: =Volume!E8 | C22: =Volume!E8 | D22: =Volume!E8 | E22: =C22-B22 | F22: =Volume!E8 (3,950 queries)
A23: AI Self-Serve Resolution Rate % | B23: 0 | C23: =Assumptions!C11 | D23: =Assumptions!C12 | E23: =C23-B23 | F23: 0% vs 40.0% target vs 47.75% steady state
A24: Inquiries Resolved by AI Assistant | B24: 0 | C24: =Volume!C14 | D24: =Volume!D14 | E24: =C24-B24 | F24: Self-serve resolutions without human touch
A25: Tickets Handled by Human Agents | B25: =B22 | C25: =Volume!C15 | D25: =Volume!D15 | E25: =C25-B25 | F25: Human ticket volume (3,950 vs 2,370 vs 2,064)
A26: Average Human Handle Time per Ticket | B26: =C14 | C26: =C16 | D26: =C16 | E26: =C26-B26 | F26: 18.0 min unassisted vs 12.0 min with AI summary
A27: Total Human Support Hours Required | B27: =(B25*B26)/60 | C27: =(C25*C26)/60 | D27: =(D25*D26)/60 | E27: =C27-B27 | F27: =(Tickets * Handle Time) / 60 (1,185 hrs vs 474 hrs)
A28: Support Agents Needed (FTEs) | B28: =B27/$C$11 | C28: =C27/$C$11 | D28: =D27/$C$11 | E28: =C28-B28 | F28: Agents needed = Hours / 123.2 productive hrs (9.6 vs 3.9 agents)
A29: Gross Human Support Labor Cost | B29: =B25*$C$15 | C29: =C25*$C$17 | D29: =D25*$C$17 | E29: =C29-B29 | F29: Direct human specialist salary & loaded overhead
A30: Variable AI API Inference Cost | B30: 0 | C30: =Cost!E21 | D30: =Cost!E21 | E30: =C30-B30 | F30: Claude Haiku 4.5 API cost with 30% buffer (=₹10,732.15)
A31: Fixed Platform Upkeep & Infra | B31: 0 | C31: =Assumptions!C44 | D31: =Assumptions!C44 | E31: =C31-B31 | F31: Vector DB, cloud hosting, 0.25 FTE upkeep (=₹50,000.00)
A32: Total Monthly Support Expenditure | B32: =SUM(B29:B31) | C32: =SUM(C29:C31) | D32: =SUM(D29:D31) | E32: =C32-B32 | F32: Human-only: ~₹3.13 Lakh | With Assistant: ~₹1.86 Lakh
A33: Net Monthly Savings (INR) | B33: 0 | C33: =$B$32-C32 | D33: =$B$32-D32 | E33: =C33 | F33: Net bottom-line savings (Target: ~₹1.27 Lakh | Steady: ~₹1.43 Lakh)
A34: Net Cost Reduction (%) | B34: 0 | C34: =C33/$B$32 | D34: =D33/$B$32 | E34: =C34 | F34: Net savings % (Target: ~41% | Steady: ~46%)
A35: Annualised Net Savings (INR) | B35: 0 | C35: =C33*12 | D35: =D33*12 | E35: =C35 | F35: Target: ₹15.22 Lakhs / year | Steady: ₹17.16 Lakhs / year

Sheet Billing
A1: Cheerio AI — Packaging, Commercial Strategy & Add-On Unit Economics
A2: Strategic evaluation of packaging models • Cost to serve vs net savings • 'Done-for-you' setup add-on margin
A4: 1. STRATEGIC EVALUATION OF PACKAGING & MONETISATION OPTIONS
A5: Option # | B5: Packaging Model | C5: Commercial Mechanics | D5: Customer Adoption Impact | E5: Support Ticket Deflection | F5: Revenue vs Cost Impact | G5: Strategic Recommendation | H5: Pros & Cons Summary
A6: OPTION 1 | B6: Free in All Plans | C6: Included natively across Starter, Growth & Enterprise tiers with 30 conv/mo fair-use cap | D6: Zero friction; SMB owners get instant 1-click self-serve at point of rejection | E6: Maximum deflection: 1,580+ tickets diverted from human queue immediately | F6: ₹10.7k AI cost absorbed as COGS; unlocks ₹126.8k monthly operational labor savings | G6: STRONGLY RECOMMENDED | H6: PROS: Zero barrier to adoption; eliminates 40%+ tickets; massive 11.8x ROI on AI compute; strong retention driver. CONS: AI cost absorbed in gross margin.
A7: OPTION 2 | B7: Per-Conversation (Usage-Based) | C7: Metered charge (e.g. ₹5 per AI conversation initiated) | D7: High friction; SMB owners fear unpredictable variable billing | E7: Severe drop: users bypass AI and raise human tickets to avoid fees! | F7: Generates modest ₹15k revenue but triggers 1,500+ human tickets costing ₹118k! | G7: NOT RECOMMENDED | H7: PROS: Direct usage monetization. CONS: Perverse incentive—users avoid ₹5 fee by raising human tickets that cost Cheerio ₹79 in human labor! Massive margin destruction.
A8: OPTION 3 | B8: Pre-paid AI Credits | C8: Users purchase credit packs (e.g. 500 AI credits for ₹499) | D8: High confusion; SMB owners like Riya do not understand tokens or credit burn | E8: Low-Moderate: unspent credits cause hesitation and reluctance to seek help | F8: Small upfront cash float, but creates heavy support burden for balance disputes | G8: NOT RECOMMENDED | H8: PROS: Upfront cash collection. CONS: High cognitive overhead for Indian SMBs; support agents spend time explaining credit balances instead of resolving WhatsApp setups.
A9: OPTION 4 | B9: Plan Add-on / Tier Gated | C9: Gated to higher-tier Pro/Enterprise plans or available as ₹999/mo add-on | D9: Excludes Starter & Growth SMBs who experience 80% of onboarding failures | E9: Very poor: majority of tickets come from early-stage users who remain unassisted | F9: Misses primary business objective of unblocking customer onboarding & churn reduction | G9: NOT RECOMMENDED | H9: PROS: Potential tier upgrade incentive. CONS: Leaves 80% of onboarding users stranded on template rejections, causing churn and flooding human queue.
A11: 2. PER-BUSINESS VALUE CREATION (COST TO SERVE vs NET OPERATIONAL SAVING)
A12: Ref # | B12: Per-Business Financial Metric | C12: Value (INR) | D12: Unit | E12: Calculation Formula & Reference | F12: Strategic Interpretation & Economics
A13: B_BIZ | B13: Total Active Business Base | C13: =Assumptions!C6 | D13: Businesses | E13: =Assumptions!C6 | F13: Active customer base paying monthly subscription
A14: B_CST_VAR | B14: Variable AI Compute Cost to Serve per Business | C14: =Cost!D27 | D14: INR / biz / mo | E14: =Cost!D27 | F14: Incremental compute cost incurred per active business (₹2.15 / mo)
A15: B_CST_TOT | B15: Fully-Loaded Platform Cost to Serve per Business | C15: =Cost!D28 | D15: INR / biz / mo | E15: =Cost!D28 | F15: Fully absorbed cost including fixed infra upkeep (₹12.15 / mo)
A16: B_SAV_GROSS | B16: Gross Human Support Labor Savings per Business | C16: =(Savings!B29-Savings!C29)/C13 | D16: INR / biz / mo | E16: =(Human Labor Status Quo - Assisted Labor) / Businesses | F16: Labor expense avoided per business (₹37.51 / mo)
A17: B_SAV_NET | B17: Net Operational Saving per Business | C17: =Savings!C33/C13 | D17: INR / biz / mo | E17: =Savings!C33 / 5,000 Businesses | F17: ₹25.37 net monthly bottom-line profit expansion per business
A18: B_ROI_VAR | B18: ROI Multiple on Variable AI Compute | C18: =C17/C14 | D18: Multiple (x) | E18: =Net Saving per Biz / Variable Cost per Biz | F18: 11.8x ROI: Every ₹1.00 spent on AI compute yields ₹11.80 in net support labor saved
A19: B_ROI_TOT | B19: ROI Multiple on Fully-Loaded Platform Cost | C19: =C17/C15 | D19: Multiple (x) | E19: =Net Saving per Biz / Fully-Loaded Cost per Biz | F19: 2.1x net return even after fully absorbing ₹50,000/mo fixed infra & upkeep
A21: 3. 'DONE-FOR-YOU' SETUP ADD-ON MARGIN & REVENUE CONTRIBUTION
A22: Line Item # | B22: Setup Service Revenue & Cost Component | C22: Amount (INR) | D22: % of Retail Price | E22: Calculation Logic | F22: Service Scope & Delivery Specifications
A23: DFY_REV | B23: Retail Price: Done-For-You WhatsApp Setup Add-On | C23: =Assumptions!C45 | D23: 100.0% | E23: =Assumptions!C45 | F23: White-glove Meta WABA registration, green tick application & template approval
A24: DFY_AG_HRS | B24: Dedicated Support Specialist Time | C24: =Assumptions!C46 | D24: - | E24: =Assumptions!C46 | F24: 2.0 hands-on specialist hours per customer setup
A25: DFY_AG_RATE | B25: Loaded Human Labor Cost per Productive Hour | C25: =Assumptions!C39 | D25: - | E25: =Assumptions!C39 | F25: ₹263.80 fully loaded specialist labor cost per productive hour
A26: DFY_CST_HUM | B26: Direct Human Labor Cost per Setup | C26: =C24*C25 | D26: =C26/$C$23 | E26: =Specialist Hours * Hourly Rate | F26: ₹527.60 direct labor cost to deliver the white-glove setup
A27: DFY_QRY_NUM | B27: Setup Inquiries Handled by AI Assistant | C27: =Assumptions!C8 | D27: - | E27: =Assumptions!C8 | F27: 3.0 automated assistant turns during initial onboarding
A28: DFY_CST_AI | B28: AI Assistant Compute Cost per Setup | C28: =C27*Cost!C17 | D28: =C28/$C$23 | E28: =Setup Queries * Cost per Conv (₹2.72) | F28: ₹8.15 automated diagnostic checks & template validations
A29: DFY_CST_TOT | B29: Total Direct Cost of Delivery per Setup | C29: =C26+C28 | D29: =C29/$C$23 | E29: =Direct Labor Cost + AI Assistant Cost | F29: ₹535.75 total direct cost to deliver setup service
A30: DFY_GP | B30: Gross Profit per Done-For-You Setup | C30: =C23-C29 | D30: =C30/$C$23 | E30: =Retail Price - Total Direct Cost | F30: ₹1,463.25 net gross profit contribution per customer setup
A31: DFY_MARGIN | B31: Gross Margin (%) | C31: =C30/C23 | D31: =C31 | E31: =Gross Profit / Retail Price | F31: Expected margin: ~73% (73.20% matches prompt expectation)

Sheet Sensitivity
A1: Cheerio AI — Sensitivity & Scenario Analysis
A2: Live sensitivity tables with formulas • Impact of AI resolution rate and escalated handle time on monthly savings & headcount
A4: TABLE 1: MONTHLY SAVINGS & HEADCOUNT vs AI RESOLUTION RATE
A5: Note: Evaluates financial savings and support agent requirements across varying AI resolution rates (20% to 60%) at baseline 12 min escalated handle time.
A6: AI Resolution Rate % | B6: Resolved Queries | C6: Escalated Queries | D6: Escalated Human Cost (INR) | E6: AI Variable Cost (INR) | F6: Fixed Cost (INR) | G6: Total Support Cost (INR) | H6: Monthly Net Saving (INR) | I6: Net Saving % | J6: Support Agents Needed (FTEs)
A7: 0.2 | B7: =Volume!$E$8*A7 | C7: =Volume!$E$8*(1-A7) | D7: =C7*Savings!$C$17 | E7: =Cost!$E$21 | F7: =Assumptions!$C$44 | G7: =D7+E7+F7 | H7: =Savings!$B$32-G7 | I7: =H7/Savings!$B$32 | J7: =(C7*Assumptions!$C$43/60)/Assumptions!$C$38
A8: 0.3 | B8: =Volume!$E$8*A8 | C8: =Volume!$E$8*(1-A8) | D8: =C8*Savings!$C$17 | E8: =Cost!$E$21 | F8: =Assumptions!$C$44 | G8: =D8+E8+F8 | H8: =Savings!$B$32-G8 | I8: =H8/Savings!$B$32 | J8: =(C8*Assumptions!$C$43/60)/Assumptions!$C$38
A9: 0.4 | B9: =Volume!$E$8*A9 | C9: =Volume!$E$8*(1-A9) | D9: =C9*Savings!$C$17 | E9: =Cost!$E$21 | F9: =Assumptions!$C$44 | G9: =D9+E9+F9 | H9: =Savings!$B$32-G9 | I9: =H9/Savings!$B$32 | J9: =(C9*Assumptions!$C$43/60)/Assumptions!$C$38
A10: =Assumptions!$C$12 | B10: =Volume!$E$8*A10 | C10: =Volume!$E$8*(1-A10) | D10: =C10*Savings!$C$17 | E10: =Cost!$E$21 | F10: =Assumptions!$C$44 | G10: =D10+E10+F10 | H10: =Savings!$B$32-G10 | I10: =H10/Savings!$B$32 | J10: =(C10*Assumptions!$C$43/60)/Assumptions!$C$38
A11: 0.5 | B11: =Volume!$E$8*A11 | C11: =Volume!$E$8*(1-A11) | D11: =C11*Savings!$C$17 | E11: =Cost!$E$21 | F11: =Assumptions!$C$44 | G11: =D11+E11+F11 | H11: =Savings!$B$32-G11 | I11: =H11/Savings!$B$32 | J11: =(C11*Assumptions!$C$43/60)/Assumptions!$C$38
A12: 0.6 | B12: =Volume!$E$8*A12 | C12: =Volume!$E$8*(1-A12) | D12: =C12*Savings!$C$17 | E12: =Cost!$E$21 | F12: =Assumptions!$C$44 | G12: =D12+E12+F12 | H12: =Savings!$B$32-G12 | I12: =H12/Savings!$B$32 | J12: =(C12*Assumptions!$C$43/60)/Assumptions!$C$38
A15: TABLE 2: MONTHLY SAVINGS & HEADCOUNT vs ESCALATED HANDLE TIME
A16: Note: Evaluates financial savings and support agent requirements across varying human handle times (8 to 18 min) for 2,370 escalated tickets (at 40% resolution target).
A17: Escalated Handle Time (min) | B17: Cost per Escalated Ticket (INR) | C17: Escalated Human Cost (INR) | D17: AI Variable Cost (INR) | E17: Fixed Cost (INR) | F17: Total Support Cost (INR) | G17: Monthly Net Saving (INR) | H17: Net Saving % | I17: Support Agents Needed (FTEs) | J17: Handle Time Reduction vs Baseline
A18: 8 | B18: =(A18/60)*Assumptions!$C$39 | C18: =Volume!$C$15*B18 | D18: =Cost!$E$21 | E18: =Assumptions!$C$44 | F18: =C18+D18+E18 | G18: =Savings!$B$32-F18 | H18: =G18/Savings!$B$32 | I18: =(Volume!$C$15*A18/60)/Assumptions!$C$38 | J18: =(Assumptions!$C$42-A18)/Assumptions!$C$42
A19: 10 | B19: =(A19/60)*Assumptions!$C$39 | C19: =Volume!$C$15*B19 | D19: =Cost!$E$21 | E19: =Assumptions!$C$44 | F19: =C19+D19+E19 | G19: =Savings!$B$32-F19 | H19: =G19/Savings!$B$32 | I19: =(Volume!$C$15*A19/60)/Assumptions!$C$38 | J19: =(Assumptions!$C$42-A19)/Assumptions!$C$42
A20: 12 | B20: =(A20/60)*Assumptions!$C$39 | C20: =Volume!$C$15*B20 | D20: =Cost!$E$21 | E20: =Assumptions!$C$44 | F20: =C20+D20+E20 | G20: =Savings!$B$32-F20 | H20: =G20/Savings!$B$32 | I20: =(Volume!$C$15*A20/60)/Assumptions!$C$38 | J20: =(Assumptions!$C$42-A20)/Assumptions!$C$42
A21: 15 | B21: =(A21/60)*Assumptions!$C$39 | C21: =Volume!$C$15*B21 | D21: =Cost!$E$21 | E21: =Assumptions!$C$44 | F21: =C21+D21+E21 | G21: =Savings!$B$32-F21 | H21: =G21/Savings!$B$32 | I21: =(Volume!$C$15*A21/60)/Assumptions!$C$38 | J21: =(Assumptions!$C$42-A21)/Assumptions!$C$42
A22: 18 | B22: =(A22/60)*Assumptions!$C$39 | C22: =Volume!$C$15*B22 | D22: =Cost!$E$21 | E22: =Assumptions!$C$44 | F22: =C22+D22+E22 | G22: =Savings!$B$32-F22 | H22: =G22/Savings!$B$32 | I22: =(Volume!$C$15*A22/60)/Assumptions!$C$38 | J22: =(Assumptions!$C$42-A22)/Assumptions!$C$42

Sheet Audit
A1: Cheerio AI — Quality, Financial Governance & Alert Threshold Matrix
A2: Production monitoring checklist • Financial variance thresholds • Operational guardrails & incident escalation paths
A4: 1. PRODUCTION ALERT THRESHOLDS & MONITORING PROTOCOL
A5: Check # | B5: Audit / Governance Check | C5: Alert Threshold | D5: Monitoring Frequency | E5: Designated Owner | F5: Action Protocol if Threshold Breached | G5: Severity Level
A6: AUD_01 | B6: Provider Invoice vs Internal Token Ledger | C6: Provider bill exceeds internal token ledger by > 5.0% variance | D6: Monthly | E6: Lead AI Engineer / FinOps | F6: Audit prompt caching hit-rate, retry multiplier, and raw HTTP API traffic. Reconcile token telemetry with Anthropic billing console. Investigate potential API key leakage or zombie worker processes. | G6: High
A7: AUD_02 | B7: Cost per Conversation Ceiling | C7: Blended cost exceeds ₹4.00 per conversation (vs ₹2.72 baseline) | D7: Weekly | E7: FinOps & AI Tech Lead | F7: Inspect conversation turn length and tool call counts. Check if recent prompt release caused token bloat in system instructions or context payloads. Roll back prompt if unnecessary overhead detected. | G7: High
A8: AUD_03 | B8: Daily API Burn vs Budget Run-Rate | C8: Daily API spend exceeds 80% of daily run-rate on ₹15,000 monthly budget (> ₹400.00 / day) | D8: Daily (Automated) | E8: Support Operations Lead | F8: Trigger automated Slack alert to On-Call Engineer. Check for scraping loops, runaway client polling, or unexpected viral inbound campaign traffic. Temporarily throttle non-essential background evaluations. | G8: Critical
A9: AUD_04 | B9: Single Conversation Token Bloat | C9: Individual conversation exceeds 40,000 tokens (vs 18,750 baseline) | D9: Real-time (Automated) | E9: Lead AI Engineer | F9: Enforce hard conversation turn limit (max 8 turns). Truncate older context history and force immediate structured handoff to human support with current conversation summary. | G9: Medium
A10: AUD_05 | B10: Account Fair-Use Cap Violation | C10: Single business exceeds 30 conversations/month or 50 conversations in 24 hours | D10: Daily / Real-time | E10: Support Operations Lead | F10: Soft-cap Ask Cheerio drawer for target account. Display polite user modal: 'Fair-use limit reached. Connecting you to dedicated account manager.' Investigate account for automated bot abuse. | G10: Medium
A11: AUD_06 | B11: AI Resolution Rate WoW Degradation | C11: AI resolution rate drops by > 5.0 percentage points week-over-week | D11: Weekly | E11: Product Manager (AI) | F11: Audit unhandled customer intents and recent Meta API updates (e.g. new rejection reason codes or policy wording). Review prompt classification logs and patch few-shot retrieval examples. | G11: High
A12: AUD_07 | B12: High Escalation Queue Surge | C12: Monthly escalation rate exceeds 70.0% (resolution drops below 30.0%) | D12: Weekly / Monthly | E12: Head of Customer Support | F12: Analyze top escalation categories in clustering dashboard. Expand deterministic 1-click fix card coverage for top failing flows. Conduct support team sync to identify emerging platform bugs. | G12: High
A13: AUD_08 | B13: Resolved Ticket Reopen Rate | C13: Resolved tickets reopened by customer within 48 hours exceeds 15.0% | D13: Weekly | E13: Support QA Lead | F13: Spot-audit 50 randomly sampled closed conversations. Determine whether AI provided incomplete instructions or if Meta subsequently rejected previously fixed templates. Calibrate confidence thresholds. | G13: Medium
A14: AUD_09 | B14: Wrong-Answer & Hallucination Rate | C14: Hallucination, policy violation, or incorrect compliance guidance exceeds 5.0% of QA audit sample | D14: Weekly / Monthly | E14: AI Safety & Product Lead | F14: Immediate prompt rollback or hotfix. Review few-shot guardrails and enforce strict deterministic tool call schema. Escalate high-risk compliance topics straight to human specialists. | G14: Critical
A16: 2. LIVE AUDIT METRIC BASELINE vs THRESHOLD BENCHMARKS
A17: Metric Description | B17: Model Baseline (Expected) | C17: Audit Alert Threshold | D17: Variance Buffer | E17: Source Reference | F17: Automated Alert Action
A18: Monthly AI API Expenditure | B18: =Cost!E21 | C18: 15000 | D18: =C18-B18 | E18: =Cost!E21 | F18: Finance alert when invoice projection hits ₹13.5k (90%)
A19: Daily Average API Spend | B19: =Cost!E21/30 | C19: 400 | D19: =C19-B19 | E19: =(Cost!E21/30) | F19: Automated daily Slack webhook alert if spend > ₹400 / day
A20: Cost per Customer Conversation | B20: =Cost!C17 | C20: 4 | D20: =C20-B20 | E20: =Cost!C17 | F20: Engineering flag if weekly average cost > ₹4.00 / conversation
A21: Tokens per Customer Conversation | B21: =Cost!C10 | C21: 40000 | D21: =C21-B21 | E21: =Cost!C10 | F21: Real-time context window truncation and human handoff
A22: Monthly Inbound Conversations / Biz | B22: =Volume!E8/Assumptions!C6 | C22: 30 | D22: =C22-B22 | E22: =Assumptions!C47 | F22: Fair-use account throttle & concierge contact
A23: Month-3 Target Resolution Rate | B23: =Assumptions!C11 | C23: 0.3 | D23: =B23-C23 | E23: =Assumptions!C11 | F23: Prompt triage & intent cluster expansion if res < 30%
